2025-06-01 12:23:40.344 | ERROR    | hcaptcha_challenger.agent.challenger:_solve_captcha:864 - ChallengeException - type=image_drag_single err=FileNotFoundError('Could not load image from tmp\\.challenge\\image_drag_drop\\Ρlease drag the shape on the right to its missing position in the pattern\\20250601\\20250601122338427858\\20250601122338427858_0_challenge_view.png')
Traceback (most recent call last):
  File "<frozen runpy>", line 198, in _run_module_as_main
  File "<frozen runpy>", line 88, in _run_code
  File "C:\Users\Vlad\Downloads\epic-awesome-gamer-main\epic-awesome-gamer-main\src\epic_awesome_gamer\cli\main.py", line 151, in <module>
    main()
  File "C:\Users\Vlad\Downloads\epic-awesome-gamer-main\epic-awesome-gamer-main\src\epic_awesome_gamer\cli\main.py", line 147, in main
    app()
  File "C:\Users\Vlad\Downloads\epic-awesome-gamer-main\epic-awesome-gamer-main\venv\Lib\site-packages\typer\main.py", line 324, in __call__
    return get_command(self)(*args, **kwargs)
  File "C:\Users\Vlad\Downloads\epic-awesome-gamer-main\epic-awesome-gamer-main\venv\Lib\site-packages\click\core.py", line 1442, in __call__
    return self.main(*args, **kwargs)
  File "C:\Users\Vlad\Downloads\epic-awesome-gamer-main\epic-awesome-gamer-main\venv\Lib\site-packages\typer\core.py", line 757, in main
    return _main(
  File "C:\Users\Vlad\Downloads\epic-awesome-gamer-main\epic-awesome-gamer-main\venv\Lib\site-packages\typer\core.py", line 195, in _main
    rv = self.invoke(ctx)
  File "C:\Users\Vlad\Downloads\epic-awesome-gamer-main\epic-awesome-gamer-main\venv\Lib\site-packages\click\core.py", line 1830, in invoke
    return _process_result(sub_ctx.command.invoke(sub_ctx))
  File "C:\Users\Vlad\Downloads\epic-awesome-gamer-main\epic-awesome-gamer-main\venv\Lib\site-packages\click\core.py", line 1226, in invoke
    return ctx.invoke(self.callback, **ctx.params)
  File "C:\Users\Vlad\Downloads\epic-awesome-gamer-main\epic-awesome-gamer-main\venv\Lib\site-packages\click\core.py", line 794, in invoke
    return callback(*args, **kwargs)
  File "C:\Users\Vlad\Downloads\epic-awesome-gamer-main\epic-awesome-gamer-main\venv\Lib\site-packages\typer\main.py", line 699, in wrapper
    return callback(**use_params)
  File "C:\Users\Vlad\Downloads\epic-awesome-gamer-main\epic-awesome-gamer-main\src\epic_awesome_gamer\cli\main.py", line 143, in collect
    asyncio.run(run_collector())
  File "C:\Users\Vlad\AppData\Local\Programs\Python\Python312\Lib\asyncio\runners.py", line 194, in run
    return runner.run(main)
  File "C:\Users\Vlad\AppData\Local\Programs\Python\Python312\Lib\asyncio\runners.py", line 118, in run
    return self._loop.run_until_complete(task)
  File "C:\Users\Vlad\AppData\Local\Programs\Python\Python312\Lib\asyncio\base_events.py", line 651, in run_until_complete
    self.run_forever()
  File "C:\Users\Vlad\AppData\Local\Programs\Python\Python312\Lib\asyncio\windows_events.py", line 321, in run_forever
    super().run_forever()
  File "C:\Users\Vlad\AppData\Local\Programs\Python\Python312\Lib\asyncio\base_events.py", line 618, in run_forever
    self._run_once()
  File "C:\Users\Vlad\AppData\Local\Programs\Python\Python312\Lib\asyncio\base_events.py", line 1951, in _run_once
    handle._run()
  File "C:\Users\Vlad\AppData\Local\Programs\Python\Python312\Lib\asyncio\events.py", line 84, in _run
    self._context.run(self._callback, *self._args)
  File "C:\Users\Vlad\Downloads\epic-awesome-gamer-main\epic-awesome-gamer-main\src\epic_awesome_gamer\cli\main.py", line 141, in run_collector
    await startup_epic_awesome_gamer(page)
  File "C:\Users\Vlad\Downloads\epic-awesome-gamer-main\epic-awesome-gamer-main\src\epic_awesome_gamer\cli\main.py", line 131, in startup_epic_awesome_gamer
    await agent.collect_epic_games()
  File "C:\Users\Vlad\Downloads\epic-awesome-gamer-main\epic-awesome-gamer-main\src\epic_awesome_gamer\collector.py", line 111, in collect_epic_games
    if not await self.epic_games.authorize(self.page):
  File "C:\Users\Vlad\Downloads\epic-awesome-gamer-main\epic-awesome-gamer-main\src\epic_awesome_gamer\epic_games.py", line 239, in authorize
    return await self._authorize(page)
  File "C:\Users\Vlad\Downloads\epic-awesome-gamer-main\epic-awesome-gamer-main\src\epic_awesome_gamer\epic_games.py", line 194, in _authorize
    await agent.wait_for_challenge()
  File "C:\Users\Vlad\Downloads\epic-awesome-gamer-main\epic-awesome-gamer-main\venv\Lib\site-packages\hcaptcha_challenger\agent\challenger.py", line 874, in wait_for_challenge
    await asyncio.wait_for(self._solve_captcha(), timeout=self.config.EXECUTION_TIMEOUT)
  File "C:\Users\Vlad\AppData\Local\Programs\Python\Python312\Lib\asyncio\tasks.py", line 510, in wait_for
    return await fut
> File "C:\Users\Vlad\Downloads\epic-awesome-gamer-main\epic-awesome-gamer-main\venv\Lib\site-packages\hcaptcha_challenger\agent\challenger.py", line 844, in _solve_captcha
    return await self.robotic_arm.challenge_image_drag_drop(challenge_type)
  File "C:\Users\Vlad\Downloads\epic-awesome-gamer-main\epic-awesome-gamer-main\venv\Lib\site-packages\hcaptcha_challenger\agent\challenger.py", line 587, in challenge_image_drag_drop
    raw, projection = await self._capture_spatial_mapping(frame_challenge, cache_key, cid)
  File "C:\Users\Vlad\Downloads\epic-awesome-gamer-main\epic-awesome-gamer-main\venv\Lib\site-packages\hcaptcha_challenger\agent\challenger.py", line 465, in _capture_spatial_mapping
    result = create_coordinate_grid(
  File "C:\Users\Vlad\Downloads\epic-awesome-gamer-main\epic-awesome-gamer-main\venv\Lib\site-packages\hcaptcha_challenger\helper\create_coordinate_grid.py", line 138, in create_coordinate_grid
    raise FileNotFoundError(f"Could not load image from {image}")
FileNotFoundError: Could not load image from tmp\.challenge\image_drag_drop\Ρlease drag the shape on the right to its missing position in the pattern\20250601\20250601122338427858\20250601122338427858_0_challenge_view.png
2025-06-01 12:26:25.202 | ERROR    | hcaptcha_challenger.agent.challenger:_solve_captcha:864 - ChallengeException - type=image_drag_single err=RetryError(<Future at 0x228ea3c62d0 state=finished raised ClientError>)
Traceback (most recent call last):
  File "C:\Users\Vlad\Downloads\epic-awesome-gamer-main\epic-awesome-gamer-main\venv\Lib\site-packages\tenacity\asyncio\__init__.py", line 114, in __call__
    result = await fn(*args, **kwargs)
  File "C:\Users\Vlad\Downloads\epic-awesome-gamer-main\epic-awesome-gamer-main\venv\Lib\site-packages\hcaptcha_challenger\tools\spatial_path_reasoning.py", line 169, in invoke_async
    self._response = await client.aio.models.generate_content(
  File "C:\Users\Vlad\Downloads\epic-awesome-gamer-main\epic-awesome-gamer-main\venv\Lib\site-packages\google\genai\models.py", line 7453, in generate_content
    response = await self._generate_content(
  File "C:\Users\Vlad\Downloads\epic-awesome-gamer-main\epic-awesome-gamer-main\venv\Lib\site-packages\google\genai\models.py", line 6447, in _generate_content
    response_dict = await self._api_client.async_request(
  File "C:\Users\Vlad\Downloads\epic-awesome-gamer-main\epic-awesome-gamer-main\venv\Lib\site-packages\google\genai\_api_client.py", line 799, in async_request
    result = await self._async_request(http_request=http_request, stream=False)
  File "C:\Users\Vlad\Downloads\epic-awesome-gamer-main\epic-awesome-gamer-main\venv\Lib\site-packages\google\genai\_api_client.py", line 743, in _async_request
    await errors.APIError.raise_for_async_response(response)
  File "C:\Users\Vlad\Downloads\epic-awesome-gamer-main\epic-awesome-gamer-main\venv\Lib\site-packages\google\genai\errors.py", line 129, in raise_for_async_response
    raise ClientError(status_code, response_json, response)
google.genai.errors.ClientError: 429 RESOURCE_EXHAUSTED. {'error': {'code': 429, 'message': 'You exceeded your current quota, please check your plan and billing details. For more information on this error, head to: https://ai.google.dev/gemini-api/docs/rate-limits.', 'status': 'RESOURCE_EXHAUSTED', 'details': [{'@type': 'type.googleapis.com/google.rpc.QuotaFailure', 'violations': [{'quotaMetric': 'generativelanguage.googleapis.com/generate_requests_per_model_per_day', 'quotaId': 'GenerateRequestsPerDayPerProjectPerModel'}, {'quotaMetric': 'generativelanguage.googleapis.com/generate_content_free_tier_requests', 'quotaId': 'GenerateRequestsPerMinutePerProjectPerModel-FreeTier', 'quotaDimensions': {'model': 'gemini-2.0-pro-exp', 'location': 'global'}}, {'quotaMetric': 'generativelanguage.googleapis.com/generate_content_free_tier_requests', 'quotaId': 'GenerateRequestsPerDayPerProjectPerModel-FreeTier', 'quotaDimensions': {'location': 'global', 'model': 'gemini-2.0-pro-exp'}}, {'quotaMetric': 'generativelanguage.googleapis.com/generate_content_free_tier_input_token_count', 'quotaId': 'GenerateContentInputTokensPerModelPerDay-FreeTier', 'quotaDimensions': {'location': 'global', 'model': 'gemini-2.0-pro-exp'}}, {'quotaMetric': 'generativelanguage.googleapis.com/generate_content_free_tier_input_token_count', 'quotaId': 'GenerateContentInputTokensPerModelPerMinute-FreeTier', 'quotaDimensions': {'location': 'global', 'model': 'gemini-2.0-pro-exp'}}]}, {'@type': 'type.googleapis.com/google.rpc.Help', 'links': [{'description': 'Learn more about Gemini API quotas', 'url': 'https://ai.google.dev/gemini-api/docs/rate-limits'}]}, {'@type': 'type.googleapis.com/google.rpc.RetryInfo', 'retryDelay': '45s'}]}}

The above exception was the direct cause of the following exception:

Traceback (most recent call last):
  File "<frozen runpy>", line 198, in _run_module_as_main
  File "<frozen runpy>", line 88, in _run_code
  File "C:\Users\Vlad\Downloads\epic-awesome-gamer-main\epic-awesome-gamer-main\src\epic_awesome_gamer\cli\main.py", line 151, in <module>
    main()
  File "C:\Users\Vlad\Downloads\epic-awesome-gamer-main\epic-awesome-gamer-main\src\epic_awesome_gamer\cli\main.py", line 147, in main
    app()
  File "C:\Users\Vlad\Downloads\epic-awesome-gamer-main\epic-awesome-gamer-main\venv\Lib\site-packages\typer\main.py", line 324, in __call__
    return get_command(self)(*args, **kwargs)
  File "C:\Users\Vlad\Downloads\epic-awesome-gamer-main\epic-awesome-gamer-main\venv\Lib\site-packages\click\core.py", line 1442, in __call__
    return self.main(*args, **kwargs)
  File "C:\Users\Vlad\Downloads\epic-awesome-gamer-main\epic-awesome-gamer-main\venv\Lib\site-packages\typer\core.py", line 757, in main
    return _main(
  File "C:\Users\Vlad\Downloads\epic-awesome-gamer-main\epic-awesome-gamer-main\venv\Lib\site-packages\typer\core.py", line 195, in _main
    rv = self.invoke(ctx)
  File "C:\Users\Vlad\Downloads\epic-awesome-gamer-main\epic-awesome-gamer-main\venv\Lib\site-packages\click\core.py", line 1830, in invoke
    return _process_result(sub_ctx.command.invoke(sub_ctx))
  File "C:\Users\Vlad\Downloads\epic-awesome-gamer-main\epic-awesome-gamer-main\venv\Lib\site-packages\click\core.py", line 1226, in invoke
    return ctx.invoke(self.callback, **ctx.params)
  File "C:\Users\Vlad\Downloads\epic-awesome-gamer-main\epic-awesome-gamer-main\venv\Lib\site-packages\click\core.py", line 794, in invoke
    return callback(*args, **kwargs)
  File "C:\Users\Vlad\Downloads\epic-awesome-gamer-main\epic-awesome-gamer-main\venv\Lib\site-packages\typer\main.py", line 699, in wrapper
    return callback(**use_params)
  File "C:\Users\Vlad\Downloads\epic-awesome-gamer-main\epic-awesome-gamer-main\src\epic_awesome_gamer\cli\main.py", line 143, in collect
    asyncio.run(run_collector())
  File "C:\Users\Vlad\AppData\Local\Programs\Python\Python312\Lib\asyncio\runners.py", line 194, in run
    return runner.run(main)
  File "C:\Users\Vlad\AppData\Local\Programs\Python\Python312\Lib\asyncio\runners.py", line 118, in run
    return self._loop.run_until_complete(task)
  File "C:\Users\Vlad\AppData\Local\Programs\Python\Python312\Lib\asyncio\base_events.py", line 651, in run_until_complete
    self.run_forever()
  File "C:\Users\Vlad\AppData\Local\Programs\Python\Python312\Lib\asyncio\windows_events.py", line 321, in run_forever
    super().run_forever()
  File "C:\Users\Vlad\AppData\Local\Programs\Python\Python312\Lib\asyncio\base_events.py", line 618, in run_forever
    self._run_once()
  File "C:\Users\Vlad\AppData\Local\Programs\Python\Python312\Lib\asyncio\base_events.py", line 1951, in _run_once
    handle._run()
  File "C:\Users\Vlad\AppData\Local\Programs\Python\Python312\Lib\asyncio\events.py", line 84, in _run
    self._context.run(self._callback, *self._args)
  File "C:\Users\Vlad\Downloads\epic-awesome-gamer-main\epic-awesome-gamer-main\src\epic_awesome_gamer\cli\main.py", line 141, in run_collector
    await startup_epic_awesome_gamer(page)
  File "C:\Users\Vlad\Downloads\epic-awesome-gamer-main\epic-awesome-gamer-main\src\epic_awesome_gamer\cli\main.py", line 131, in startup_epic_awesome_gamer
    await agent.collect_epic_games()
  File "C:\Users\Vlad\Downloads\epic-awesome-gamer-main\epic-awesome-gamer-main\src\epic_awesome_gamer\collector.py", line 111, in collect_epic_games
    if not await self.epic_games.authorize(self.page):
  File "C:\Users\Vlad\Downloads\epic-awesome-gamer-main\epic-awesome-gamer-main\src\epic_awesome_gamer\epic_games.py", line 239, in authorize
    return await self._authorize(page)
  File "C:\Users\Vlad\Downloads\epic-awesome-gamer-main\epic-awesome-gamer-main\src\epic_awesome_gamer\epic_games.py", line 194, in _authorize
    await agent.wait_for_challenge()
  File "C:\Users\Vlad\Downloads\epic-awesome-gamer-main\epic-awesome-gamer-main\venv\Lib\site-packages\hcaptcha_challenger\agent\challenger.py", line 874, in wait_for_challenge
    await asyncio.wait_for(self._solve_captcha(), timeout=self.config.EXECUTION_TIMEOUT)
  File "C:\Users\Vlad\AppData\Local\Programs\Python\Python312\Lib\asyncio\tasks.py", line 510, in wait_for
    return await fut
> File "C:\Users\Vlad\Downloads\epic-awesome-gamer-main\epic-awesome-gamer-main\venv\Lib\site-packages\hcaptcha_challenger\agent\challenger.py", line 844, in _solve_captcha
    return await self.robotic_arm.challenge_image_drag_drop(challenge_type)
  File "C:\Users\Vlad\Downloads\epic-awesome-gamer-main\epic-awesome-gamer-main\venv\Lib\site-packages\hcaptcha_challenger\agent\challenger.py", line 591, in challenge_image_drag_drop
    response = await self._spatial_path_reasoner.invoke_async(
  File "C:\Users\Vlad\Downloads\epic-awesome-gamer-main\epic-awesome-gamer-main\venv\Lib\site-packages\tenacity\asyncio\__init__.py", line 189, in async_wrapped
    return await copy(fn, *args, **kwargs)
  File "C:\Users\Vlad\Downloads\epic-awesome-gamer-main\epic-awesome-gamer-main\venv\Lib\site-packages\tenacity\asyncio\__init__.py", line 111, in __call__
    do = await self.iter(retry_state=retry_state)
  File "C:\Users\Vlad\Downloads\epic-awesome-gamer-main\epic-awesome-gamer-main\venv\Lib\site-packages\tenacity\asyncio\__init__.py", line 153, in iter
    result = await action(retry_state)
  File "C:\Users\Vlad\Downloads\epic-awesome-gamer-main\epic-awesome-gamer-main\venv\Lib\site-packages\tenacity\_utils.py", line 99, in inner
    return call(*args, **kwargs)
  File "C:\Users\Vlad\Downloads\epic-awesome-gamer-main\epic-awesome-gamer-main\venv\Lib\site-packages\tenacity\__init__.py", line 421, in exc_check
    raise retry_exc from fut.exception()
tenacity.RetryError: RetryError[<Future at 0x228ea3c62d0 state=finished raised ClientError>]
2025-06-01 12:34:03.870 | ERROR    | hcaptcha_challenger.agent.challenger:_task_handler:686 - An error occurred while injecting hsw script: Page.evaluate: "btoa" is read-only
SMBf@debugger eval code line 313 > eval:2:190298
@debugger eval code line 313 > eval:2:871603
evaluate@debugger eval code:313:29
@debugger eval code:1:44

2025-06-01 12:34:16.570 | ERROR    | hcaptcha_challenger.agent.challenger:get_challenge_frame_locator:318 - Cannot find a valid challenge frame
